import asyncio
import aiohttp
import logging

# ------------------------------------------------------------------------------
import functools
import time
from typing import Any
from collections.abc import Awaitable, Callable

from aiohttp import ClientSession


async def delay(delay_seconds: int) -> int:
    print(f"sleeping for {delay_seconds} second(s)")
    await asyncio.sleep(delay_seconds)
    print(f"finished sleeping for {delay_seconds} second(s)")
    return delay_seconds


def async_timed():
    def wrapper(
        func: Callable[..., Awaitable[Any]],
    ) -> Callable[..., Awaitable[Any]]:
        @functools.wraps(func)
        async def wrapped(*args: Any, **kwargs: Any) -> Any:
            print(f"starting {func} with args {args} {kwargs}")
            start = time.time()
            try:
                return await func(*args, **kwargs)
            finally:
                end = time.time()
                total = end - start
                print(f"finished {func} in {total:.4f} second(s)")

        return wrapped

    return wrapper


@async_timed()
async def fetch_status(session: ClientSession, url: str, delay: int = 0) -> int:
    await asyncio.sleep(delay)
    async with session.get(url) as result:
        return result.status


# ------------------------------------------------------------------------------


@async_timed()
async def main():
    async with aiohttp.ClientSession() as session:
        good_request = fetch_status(session, "https://www.example.com")
        bad_request = fetch_status(session, "python://bad")

        fetchers = [
            asyncio.create_task(good_request),
            asyncio.create_task(bad_request),
        ]

        done, pending = await asyncio.wait(fetchers)

        print(f"Done task count: {len(done)}")
        print(f"Pending task count: {len(pending)}")

        for done_task in done:
            # result = await done_task will throw an exception
            if done_task.exception() is None:
                print(done_task.result())
            else:
                logging.error(
                    "Request got an exception", exc_info=done_task.exception()
                )


asyncio.run(main())
